<?xml version="1.0" encoding="utf-8"?>
<!-- This URDF was automatically created by SolidWorks to URDF Exporter! Originally created by Stephen Brawner (brawner@gmail.com) 
     Commit Version: 1.6.0-4-g7f85cfe  Build Version: 1.6.7995.38578
     For more information, please see http://wiki.ros.org/sw_urdf_exporter -->
<robot
  name="ballrobot">
  
  <link name="robot_footprint">
    	<visual>
    		<origin xyz="0 0 0" rpy="0 0 0"/>
    		<geometry>
    			<box size="0.001 0.001 0.001"/>
    		</geometry>
    	</visual>
  </link>
    
  <gazebo reference="robot_footprint">
    	<turnGravityOff>false</turnGravityOff>
  </gazebo>
    
  <joint name="robot_footprint_joint" type="fixed">
    	<origin xyz="0 0 0.04" rpy="3.14 3.14 0"/>
    	<parent link="robot_footprint"/>
    	<child link="base_link"/>
  </joint>
  
  
  <link
    name="base_link">
    <inertial>
      <origin
        xyz="-0.060656 -3.3953E-08 0.1"
        rpy="0 0 0" />
      <mass
        value="30.128" />
      <inertia
        ixx="0.62458"
        ixy="9.5848E-08"
        ixz="2.8849E-10"
        iyy="0.70315"
        iyz="3.6924E-11"
        izz="1.2817" />
    </inertial>
    <visual>
      <origin
        xyz="0 0 0"
        rpy="0 0 0" />
      <geometry>
        <mesh
          filename="package://ballrobot/meshes/base_link.STL" />
      </geometry>
      <material
        name="">
        <color
          rgba="0.52941 0.54902 0.54902 1" />
      </material>
    </visual>
    <collision>
      <origin
        xyz="0 0 0"
        rpy="0 0 0" />
      <geometry>
        <mesh
          filename="package://ballrobot/meshes/base_link.STL" />
      </geometry>
    </collision>
  </link>
  <link
    name="FL_Wheel">
    <inertial>
      <origin
        xyz="2.7756E-17 0.01 -1.3169E-16"
        rpy="0 0 0" />
      <mass
        value="0.29309" />
      <inertia
        ixx="0.00090526"
        ixy="-4.5898E-20"
        ixz="7.9331E-19"
        iyy="0.0017973"
        iyz="-5.1941E-21"
        izz="0.00090526" />
    </inertial>
    <visual>
      <origin
        xyz="0 0 0"
        rpy="0 0 0" />
      <geometry>
        <mesh
          filename="package://ballrobot/meshes/FL_Wheel.STL" />
      </geometry>
      <material
        name="">
        <color
          rgba="0.29804 0.29804 0.29804 1" />
      </material>
    </visual>
    <collision>
      <origin
        xyz="0 0 0"
        rpy="0 0 0" />
      <geometry>
        <mesh
          filename="package://ballrobot/meshes/FL_Wheel.STL" />
      </geometry>
    </collision>
  </link>
  <joint
    name="FL_joint"
    type="continuous">
    <origin
      xyz="0.175 -0.23 0.1"
      rpy="0 0 0" />
    <parent
      link="base_link" />
    <child
      link="FL_Wheel" />
    <axis
      xyz="0 -1 0" />
    <limit
      effort="10"
      velocity="10" />
  </joint>
  <link
    name="FR_Wheel">
    <inertial>
      <origin
        xyz="-1.66533453693773E-16 -0.01 4.16748948438248E-17"
        rpy="0 0 0" />
      <mass
        value="0.293086659627673" />
      <inertia
        ixx="0.000905256868248756"
        ixy="5.99099089183777E-20"
        ixz="-1.81071936351132E-18"
        iyy="0.00179725505357009"
        iyz="-1.96091888376218E-20"
        izz="0.000905256868248957" />
    </inertial>
    <visual>
      <origin
        xyz="0 0 0"
        rpy="0 0 0" />
      <geometry>
        <mesh
          filename="package://ballrobot/meshes/FR_Wheel.STL" />
      </geometry>
      <material
        name="">
        <color
          rgba="0.298039215686275 0.298039215686275 0.298039215686275 1" />
      </material>
    </visual>
    <collision>
      <origin
        xyz="0 0 0"
        rpy="0 0 0" />
      <geometry>
        <mesh
          filename="package://ballrobot/meshes/FR_Wheel.STL" />
      </geometry>
    </collision>
  </link>
  <joint
    name="FR_joint"
    type="continuous">
    <origin
      xyz="0.175 0.23 0.1"
      rpy="0 0 0" />
    <parent
      link="base_link" />
    <child
      link="FR_Wheel" />
    <axis
      xyz="0 1 0" />
    <limit
      effort="10"
      velocity="10" />
  </joint>
  <link
    name="RL_Wheel">
    <inertial>
      <origin
        xyz="3.05311331771918E-16 0.01 -7.60494903186981E-17"
        rpy="0 0 0" />
      <mass
        value="0.293086659627673" />
      <inertia
        ixx="0.000905256868248756"
        ixy="6.51889408525683E-21"
        ixz="6.26944743178317E-20"
        iyy="0.00179725505357009"
        iyz="-2.6431409407267E-20"
        izz="0.000905256868248959" />
    </inertial>
    <visual>
      <origin
        xyz="0 0 0"
        rpy="0 0 0" />
      <geometry>
        <mesh
          filename="package://ballrobot/meshes/RL_Wheel.STL" />
      </geometry>
      <material
        name="">
        <color
          rgba="0.298039215686275 0.298039215686275 0.298039215686275 1" />
      </material>
    </visual>
    <collision>
      <origin
        xyz="0 0 0"
        rpy="0 0 0" />
      <geometry>
        <mesh
          filename="package://ballrobot/meshes/RL_Wheel.STL" />
      </geometry>
    </collision>
  </link>
  <joint
    name="RL_joint"
    type="continuous">
    <origin
      xyz="-0.175 -0.23 0.1"
      rpy="0 0 0" />
    <parent
      link="base_link" />
    <child
      link="RL_Wheel" />
    <axis
      xyz="0 -1 0" />
    <limit
      effort="10"
      velocity="10" />
  </joint>
  <link
    name="RR_Wheel">
    <inertial>
      <origin
        xyz="-1.38777878078145E-16 -0.00999999999999998 -2.19547988732742E-16"
        rpy="0 0 0" />
      <mass
        value="0.293086659627672" />
      <inertia
        ixx="0.000905256868248753"
        ixy="-6.48648136838311E-21"
        ixz="-1.08512363876318E-18"
        iyy="0.00179725505357008"
        iyz="-3.10233119385734E-20"
        izz="0.000905256868248956" />
    </inertial>
    <visual>
      <origin
        xyz="0 0 0"
        rpy="0 0 0" />
      <geometry>
        <mesh
          filename="package://ballrobot/meshes/RR_Wheel.STL" />
      </geometry>
      <material
        name="">
        <color
          rgba="0.298039215686275 0.298039215686275 0.298039215686275 1" />
      </material>
    </visual>
    <collision>
      <origin
        xyz="0 0 0"
        rpy="0 0 0" />
      <geometry>
        <mesh
          filename="package://ballrobot/meshes/RR_Wheel.STL" />
      </geometry>
    </collision>
  </link>
  <joint
    name="RR_Joint"
    type="continuous">
    <origin
      xyz="-0.175 0.23 0.1"
      rpy="0 0 0" />
    <parent
      link="base_link" />
    <child
      link="RR_Wheel" />
    <axis
      xyz="0 1 0" />
    <limit
      effort="10"
      velocity="10" />
  </joint>
  <link
    name="L_hand">
    <inertial>
      <origin
        xyz="0 0.0912922100205346 -0.0699559788439906"
        rpy="0 0 0" />
      <mass
        value="5.12382990996477" />
      <inertia
        ixx="0.0239436769326506"
        ixy="3.50383167062989E-19"
        ixz="1.54800646830182E-19"
        iyy="0.00882901814263977"
        iyz="1.96488876568737E-05"
        izz="0.0156491094539096" />
    </inertial>
    <visual>
      <origin
        xyz="0 0 0"
        rpy="0 0 0" />
      <geometry>
        <mesh
          filename="package://ballrobot/meshes/L_hand.STL" />
      </geometry>
      <material
        name="">
        <color
          rgba="0.529411764705882 0.549019607843137 0.549019607843137 1" />
      </material>
    </visual>
    <collision>
      <origin
        xyz="0 0 0"
        rpy="0 0 0" />
      <geometry>
        <mesh
          filename="package://ballrobot/meshes/L_hand.STL" />
      </geometry>
    </collision>
  </link>
  <joint
    name="LH_joint"
    type="revolute">
    <origin
      xyz="0.29 -0.1875 0.17"
      rpy="0 0 0" />
    <parent
      link="base_link" />
    <child
      link="L_hand" />
    <axis
      xyz="0 0 -1" />
    <limit
      lower="0"
      upper="3.14"
      effort="10"
      velocity="10" />
  </joint>
  <link
    name="R_hand">
    <inertial>
      <origin
        xyz="-5.5511E-17 -0.091292 -0.070044"
        rpy="0 0 0" />
      <mass
        value="5.1238" />
      <inertia
        ixx="0.023944"
        ixy="1.3029E-19"
        ixz="3.1466E-19"
        iyy="0.008829"
        iyz="1.9649E-05"
        izz="0.015649" />
    </inertial>
    <visual>
      <origin
        xyz="0 0 0"
        rpy="0 0 0" />
      <geometry>
        <mesh
          filename="package://ballrobot/meshes/R_hand.STL" />
      </geometry>
      <material
        name="">
        <color
          rgba="0.52941 0.54902 0.54902 1" />
      </material>
    </visual>
    <collision>
      <origin
        xyz="0 0 0"
        rpy="0 0 0" />
      <geometry>
        <mesh
          filename="package://ballrobot/meshes/R_hand.STL" />
      </geometry>
    </collision>
  </link>
  <joint
    name="RH_joint"
    type="revolute">
    <origin
      xyz="0.29 0.1875 0.17"
      rpy="0 0 0" />
    <parent
      link="base_link" />
    <child
      link="R_hand" />
    <axis
      xyz="0 0 -1" />
    <limit
      lower="-3.14"
      upper="0"
      effort="10"
      velocity="10" />
  </joint>
  
  
  <gazebo>
    
    <plugin name="skid_steer_drive_controller" filename="libgazebo_ros_skid_steer_drive.so">
      <updateRate>10.0</updateRate>
      
      <leftFrontJoint>FL_joint</leftFrontJoint>
      <rightFrontJoint>FR_joint</rightFrontJoint>
      <leftRearJoint>RL_joint</leftRearJoint>
      <rightRearJoint>RR_joint</rightRearJoint>
      <wheelSeparation>0.42</wheelSeparation>
      <wheelDiameter>0.2</wheelDiameter>
      <robotBaseFrame>robot_footprint</robotBaseFrame>
      <torque>10</torque>

      <topicName>cmd_vel</topicName>
      <odometryTopic>odom</odometryTopic>
      <odometryFrame>odom</odometryFrame>

      <commandTopic>cmd_vel</commandTopic>
      <topic_name_twist>cmd_vel</topic_name_twist>
      <topic_name_odometry>odom</topic_name_odometry>
      <topic_name_joint>joint</topic_name_joint>

      <broadcastTF>true</broadcastTF>

      <covariance_x>0.0001</covariance_x>
      <covariance_y>0.0001</covariance_y>
      <covariance_yaw>0.01</covariance_yaw>

    </plugin>

  </gazebo> 
  
  
</robot>
